Workbook

Sheet Útmutató
B2: 💰 Egyszerűsített pénzügyi kimutatás – útmutató
B3: Nagy Zoltán · nagyzoltan25.github.io
B5: Hogyan használd
B6: 1. Az „📊 Éves Összesítő” lapon írd be az évet (B2).
B7: 2. A hónap elején a „Tervezett” oszlopba írd be, mennyit szánsz az egyes tételekre.
B8: 3. A hónap során vagy végén az „Összeg” oszlopba írd be a tényleges összegeket.
B9: 4. Új tétel: írd be a nevét egy üres sorba (vagy írj át egy meglévőt). A következő hónapokba automatikusan átkerül, és az Éves Összesítő is magától felveszi.
B10: 5. Az „Összesítő” oszlop, a ∑ sorok, az eltérés és a havi egyenleg automatikusan számolódik – ezeket ne írd felül.
B11: 6. Eltérés a tervtől: pozitív = jobb a tervnél (több bevétel, több megtakarítás, kevesebb kiadás); piros, negatív = rosszabb a tervnél.
B12: 7. Arány: bevételi tételek a teljes bevétel %-ában, megtakarítási tételek az összes megtakarítás %-ában, kiadási tételek az összes kiadás %-ában. A megtakarítás és a kiadás összesen a bevétel %-ában.
B13: 8. Megtakarítási index: a bevétel hány százalékát tetted félre az adott hónapban.
B15: Jelmagyarázat
... B21: Ez a táblázat általános segédeszköz, nem személyre szabott pénzügyi tanácsadás.

Sheet 📊 Éves Összesítő
A1: 📊 ÉVES PÉNZÜGYI ÖSSZESÍTŐ | Q1: =SUMPRODUCT(--((B5:M5+B7:M7)>0)) -> 0
A2: Év (írd át, ha másik évet vezetsz): | B2: 2026
A4: 📈 HAVI ÖSSZEFOGLALÓ | B4: Jan | C4: Feb | D4: Már | E4: Ápr | F4: Máj | G4: Jún | H4: Júl | I4: Aug | J4: Sze | K4: Okt | L4: Nov | M4: Dec | N4: ÉVES | O4: Havi átlag* | P4: Arány
A5: 💚 Bevétel összesen | B5: =Január!C16 -> 0 | C5: =Február!C16 -> 0 | D5: =Március!C16 -> 0 | E5: =Április!C16 -> 0 | F5: =Május!C16 -> 0 | G5: =Június!C16 -> 0 | H5: =Július!C16 -> 0 | I5: =Augusztus!C16 -> 0 | J5: =Szeptember!C16 -> 0 | K5: =Október!C16 -> 0 | L5: =November!C16 -> 0 | M5: =December!C16 -> 0 | N5: =SUM(B5:M5) -> 0 | O5: =N5/MAX(1,$Q$1) -> 0 | P5: =IF(OR(N5="",$N$5=0),"",N5/$N$5)
A6: 💎 Megtakarítás összesen | B6: =Január!C28 -> 0 | C6: =Február!C28 -> 0 | D6: =Március!C28 -> 0 | E6: =Április!C28 -> 0 | F6: =Május!C28 -> 0 | G6: =Június!C28 -> 0 | H6: =Július!C28 -> 0 | I6: =Augusztus!C28 -> 0 | J6: =Szeptember!C28 -> 0 | K6: =Október!C28 -> 0 | L6: =November!C28 -> 0 | M6: =December!C28 -> 0 | N6: =SUM(B6:M6) -> 0 | O6: =N6/MAX(1,$Q$1) -> 0 | P6: =IF(OR(N6="",$N$5=0),"",N6/$N$5)
A7: ❤️ Kiadás összesen | B7: =Január!C118 -> 0 | C7: =Február!C118 -> 0 | D7: =Március!C118 -> 0 | E7: =Április!C118 -> 0 | F7: =Május!C118 -> 0 | G7: =Június!C118 -> 0 | H7: =Július!C118 -> 0 | I7: =Augusztus!C118 -> 0 | J7: =Szeptember!C118 -> 0 | K7: =Október!C118 -> 0 | L7: =November!C118 -> 0 | M7: =December!C118 -> 0 | N7: =SUM(B7:M7) -> 0 | O7: =N7/MAX(1,$Q$1) -> 0 | P7: =IF(OR(N7="",$N$5=0),"",N7/$N$5)
A8: 💰 Havi egyenleg | B8: =B5-B6-B7 -> 0 | C8: =C5-C6-C7 -> 0 | D8: =D5-D6-D7 -> 0 | E8: =E5-E6-E7 -> 0 | F8: =F5-F6-F7 -> 0 | G8: =G5-G6-G7 -> 0 | H8: =H5-H6-H7 -> 0 | I8: =I5-I6-I7 -> 0 | ... O8: =O5-O6-O7 -> 0 | P8: =IF(OR(N8="",$N$5=0),"",N8/$N$5)
A9: Megtakarítási index | B9: =IF(B5=0,"–",B6/B5) -> – | C9: =IF(C5=0,"–",C6/C5) -> – | D9: =IF(D5=0,"–",D6/D5) -> – | E9: =IF(E5=0,"–",E6/E5) -> – | F9: =IF(F5=0,"–",F6/F5) -> – | G9: =IF(G5=0,"–",G6/G5) -> – | H9: =IF(H5=0,"–",H6/H5) -> – | I9: =IF(I5=0,"–",I6/I5) -> – | ... O9: =IF(O5=0,"–",O6/O5) -> –
A10: Kumulált egyenleg (év eleje óta) | B10: =B8 -> 0 | C10: =B10+C8 -> 0 | D10: =C10+D8 -> 0 | E10: =D10+E8 -> 0 | F10: =E10+F8 -> 0 | G10: =F10+G8 -> 0 | H10: =G10+H8 -> 0 | I10: =H10+I8 -> 0 | J10: =I10+J8 -> 0 | ... M10: =L10+M8 -> 0
A11: 💚 BEVÉTELEK TÉTELENKÉNT | B11: Jan | C11: Feb | D11: Már | E11: Ápr | F11: Máj | G11: Jún | H11: Júl | I11: Aug | J11: Sze | K11: Okt | L11: Nov | M11: Dec | N11: ÉVES | O11: Havi átlag* | P11: Arány
A12: =IFERROR(INDEX(_Segéd!$A$2:$A$97,MATCH(1,_Segéd!$B$2:$B$97,0)),"") -> Munkabér 1 (pl. saját) | B12: =IF($A12="","",SUMIF(Január!$A$5:$A$14,$A12,Január!$B$5:$B$14)) -> 0 | C12: =IF($A12="","",SUMIF(Február!$A$5:$A$14,$A12,Február!$B$5:$B$14)) -> 0 | D12: =IF($A12="","",SUMIF(Március!$A$5:$A$14,$A12,Március!$B$5:$B$14)) -> 0 | E12: =IF($A12="","",SUMIF(Április!$A$5:$A$14,$A12,Április!$B$5:$B$14)) -> 0 | F12: =IF($A12="","",SUMIF(Május!$A$5:$A$14,$A12,Május!$B$5:$B$14)) -> 0 | G12: =IF($A12="","",SUMIF(Június!$A$5:$A$14,$A12,Június!$B$5:$B$14)) -> 0 | H12: =IF($A12="","",SUMIF(Július!$A$5:$A$14,$A12,Július!$B$5:$B$14)) -> 0 | I12: =IF($A12="","",SUMIF(Augusztus!$A$5:$A$14,$A12,Augusztus!$B$5:$B$14)) -> 0 | J12: =IF($A12="","",SUMIF(Szeptember!$A$5:$A$14,$A12,Szeptember!$B$5:$B$14)) -> 0 | K12: =IF($A12="","",SUMIF(Október!$A$5:$A$14,$A12,Október!$B$5:$B$14)) -> 0 | L12: =IF($A12="","",SUMIF(November!$A$5:$A$14,$A12,November!$B$5:$B$14)) -> 0 | M12: =IF($A12="","",SUMIF(December!$A$5:$A$14,$A12,December!$B$5:$B$14)) -> 0 | N12: =IF($A12="","",SUM(B12:M12)) -> 0 | O12: =IF($A12="","",N12/MAX(1,$Q$1)) -> 0 | P12: =IF(OR(N12="",$N$5=0),"",N12/$N$5)
A13: =IFERROR(INDEX(_Segéd!$A$2:$A$97,MATCH(2,_Segéd!$B$2:$B$97,0)),"") -> Munkabér 2 (pl. partner) | B13: =IF($A13="","",SUMIF(Január!$A$5:$A$14,$A13,Január!$B$5:$B$14)) -> 0 | C13: =IF($A13="","",SUMIF(Február!$A$5:$A$14,$A13,Február!$B$5:$B$14)) -> 0 | D13: =IF($A13="","",SUMIF(Március!$A$5:$A$14,$A13,Március!$B$5:$B$14)) -> 0 | E13: =IF($A13="","",SUMIF(Április!$A$5:$A$14,$A13,Április!$B$5:$B$14)) -> 0 | F13: =IF($A13="","",SUMIF(Május!$A$5:$A$14,$A13,Május!$B$5:$B$14)) -> 0 | G13: =IF($A13="","",SUMIF(Június!$A$5:$A$14,$A13,Június!$B$5:$B$14)) -> 0 | H13: =IF($A13="","",SUMIF(Július!$A$5:$A$14,$A13,Július!$B$5:$B$14)) -> 0 | I13: =IF($A13="","",SUMIF(Augusztus!$A$5:$A$14,$A13,Augusztus!$B$5:$B$14)) -> 0 | J13: =IF($A13="","",SUMIF(Szeptember!$A$5:$A$14,$A13,Szeptember!$B$5:$B$14)) -> 0 | K13: =IF($A13="","",SUMIF(Október!$A$5:$A$14,$A13,Október!$B$5:$B$14)) -> 0 | L13: =IF($A13="","",SUMIF(November!$A$5:$A$14,$A13,November!$B$5:$B$14)) -> 0 | M13: =IF($A13="","",SUMIF(December!$A$5:$A$14,$A13,December!$B$5:$B$14)) -> 0 | N13: =IF($A13="","",SUM(B13:M13)) -> 0 | O13: =IF($A13="","",N13/MAX(1,$Q$1)) -> 0 | P13: =IF(OR(N13="",$N$5=0),"",N13/$N$5)
A14: =IFERROR(INDEX(_Segéd!$A$2:$A$97,MATCH(3,_Segéd!$B$2:$B$97,0)),"") -> Vállalkozói bevétel | B14: =IF($A14="","",SUMIF(Január!$A$5:$A$14,$A14,Január!$B$5:$B$14)) -> 0 | C14: =IF($A14="","",SUMIF(Február!$A$5:$A$14,$A14,Február!$B$5:$B$14)) -> 0 | D14: =IF($A14="","",SUMIF(Március!$A$5:$A$14,$A14,Március!$B$5:$B$14)) -> 0 | E14: =IF($A14="","",SUMIF(Április!$A$5:$A$14,$A14,Április!$B$5:$B$14)) -> 0 | F14: =IF($A14="","",SUMIF(Május!$A$5:$A$14,$A14,Május!$B$5:$B$14)) -> 0 | G14: =IF($A14="","",SUMIF(Június!$A$5:$A$14,$A14,Június!$B$5:$B$14)) -> 0 | H14: =IF($A14="","",SUMIF(Július!$A$5:$A$14,$A14,Július!$B$5:$B$14)) -> 0 | I14: =IF($A14="","",SUMIF(Augusztus!$A$5:$A$14,$A14,Augusztus!$B$5:$B$14)) -> 0 | J14: =IF($A14="","",SUMIF(Szeptember!$A$5:$A$14,$A14,Szeptember!$B$5:$B$14)) -> 0 | K14: =IF($A14="","",SUMIF(Október!$A$5:$A$14,$A14,Október!$B$5:$B$14)) -> 0 | L14: =IF($A14="","",SUMIF(November!$A$5:$A$14,$A14,November!$B$5:$B$14)) -> 0 | M14: =IF($A14="","",SUMIF(December!$A$5:$A$14,$A14,December!$B$5:$B$14)) -> 0 | N14: =IF($A14="","",SUM(B14:M14)) -> 0 | O14: =IF($A14="","",N14/MAX(1,$Q$1)) -> 0 | P14: =IF(OR(N14="",$N$5=0),"",N14/$N$5)
A15: =IFERROR(INDEX(_Segéd!$A$2:$A$97,MATCH(4,_Segéd!$B$2:$B$97,0)),"") -> CSED / GYED / GYES | B15: =IF($A15="","",SUMIF(Január!$A$5:$A$14,$A15,Január!$B$5:$B$14)) -> 0 | C15: =IF($A15="","",SUMIF(Február!$A$5:$A$14,$A15,Február!$B$5:$B$14)) -> 0 | D15: =IF($A15="","",SUMIF(Március!$A$5:$A$14,$A15,Március!$B$5:$B$14)) -> 0 | E15: =IF($A15="","",SUMIF(Április!$A$5:$A$14,$A15,Április!$B$5:$B$14)) -> 0 | F15: =IF($A15="","",SUMIF(Május!$A$5:$A$14,$A15,Május!$B$5:$B$14)) -> 0 | G15: =IF($A15="","",SUMIF(Június!$A$5:$A$14,$A15,Június!$B$5:$B$14)) -> 0 | H15: =IF($A15="","",SUMIF(Július!$A$5:$A$14,$A15,Július!$B$5:$B$14)) -> 0 | I15: =IF($A15="","",SUMIF(Augusztus!$A$5:$A$14,$A15,Augusztus!$B$5:$B$14)) -> 0 | J15: =IF($A15="","",SUMIF(Szeptember!$A$5:$A$14,$A15,Szeptember!$B$5:$B$14)) -> 0 | K15: =IF($A15="","",SUMIF(Október!$A$5:$A$14,$A15,Október!$B$5:$B$14)) -> 0 | L15: =IF($A15="","",SUMIF(November!$A$5:$A$14,$A15,November!$B$5:$B$14)) -> 0 | M15: =IF($A15="","",SUMIF(December!$A$5:$A$14,$A15,December!$B$5:$B$14)) -> 0 | N15: =IF($A15="","",SUM(B15:M15)) -> 0 | O15: =IF($A15="","",N15/MAX(1,$Q$1)) -> 0 | P15: =IF(OR(N15="",$N$5=0),"",N15/$N$5)
A16: =IFERROR(INDEX(_Segéd!$A$2:$A$97,MATCH(5,_Segéd!$B$2:$B$97,0)),"") -> Családi pótlék | B16: =IF($A16="","",SUMIF(Január!$A$5:$A$14,$A16,Január!$B$5:$B$14)) -> 0 | C16: =IF($A16="","",SUMIF(Február!$A$5:$A$14,$A16,Február!$B$5:$B$14)) -> 0 | D16: =IF($A16="","",SUMIF(Március!$A$5:$A$14,$A16,Március!$B$5:$B$14)) -> 0 | E16: =IF($A16="","",SUMIF(Április!$A$5:$A$14,$A16,Április!$B$5:$B$14)) -> 0 | F16: =IF($A16="","",SUMIF(Május!$A$5:$A$14,$A16,Május!$B$5:$B$14)) -> 0 | G16: =IF($A16="","",SUMIF(Június!$A$5:$A$14,$A16,Június!$B$5:$B$14)) -> 0 | H16: =IF($A16="","",SUMIF(Július!$A$5:$A$14,$A16,Július!$B$5:$B$14)) -> 0 | I16: =IF($A16="","",SUMIF(Augusztus!$A$5:$A$14,$A16,Augusztus!$B$5:$B$14)) -> 0 | J16: =IF($A16="","",SUMIF(Szeptember!$A$5:$A$14,$A16,Szeptember!$B$5:$B$14)) -> 0 | K16: =IF($A16="","",SUMIF(Október!$A$5:$A$14,$A16,Október!$B$5:$B$14)) -> 0 | L16: =IF($A16="","",SUMIF(November!$A$5:$A$14,$A16,November!$B$5:$B$14)) -> 0 | M16: =IF($A16="","",SUMIF(December!$A$5:$A$14,$A16,December!$B$5:$B$14)) -> 0 | N16: =IF($A16="","",SUM(B16:M16)) -> 0 | O16: =IF($A16="","",N16/MAX(1,$Q$1)) -> 0 | P16: =IF(OR(N16="",$N$5=0),"",N16/$N$5)
A17: =IFERROR(INDEX(_Segéd!$A$2:$A$97,MATCH(6,_Segéd!$B$2:$B$97,0)),"") -> Egyéb (lakáskiadás, bónusz stb.) | B17: =IF($A17="","",SUMIF(Január!$A$5:$A$14,$A17,Január!$B$5:$B$14)) -> 0 | C17: =IF($A17="","",SUMIF(Február!$A$5:$A$14,$A17,Február!$B$5:$B$14)) -> 0 | D17: =IF($A17="","",SUMIF(Március!$A$5:$A$14,$A17,Március!$B$5:$B$14)) -> 0 | E17: =IF($A17="","",SUMIF(Április!$A$5:$A$14,$A17,Április!$B$5:$B$14)) -> 0 | F17: =IF($A17="","",SUMIF(Május!$A$5:$A$14,$A17,Május!$B$5:$B$14)) -> 0 | G17: =IF($A17="","",SUMIF(Június!$A$5:$A$14,$A17,Június!$B$5:$B$14)) -> 0 | H17: =IF($A17="","",SUMIF(Július!$A$5:$A$14,$A17,Július!$B$5:$B$14)) -> 0 | I17: =IF($A17="","",SUMIF(Augusztus!$A$5:$A$14,$A17,Augusztus!$B$5:$B$14)) -> 0 | J17: =IF($A17="","",SUMIF(Szeptember!$A$5:$A$14,$A17,Szeptember!$B$5:$B$14)) -> 0 | K17: =IF($A17="","",SUMIF(Október!$A$5:$A$14,$A17,Október!$B$5:$B$14)) -> 0 | L17: =IF($A17="","",SUMIF(November!$A$5:$A$14,$A17,November!$B$5:$B$14)) -> 0 | M17: =IF($A17="","",SUMIF(December!$A$5:$A$14,$A17,December!$B$5:$B$14)) -> 0 | N17: =IF($A17="","",SUM(B17:M17)) -> 0 | O17: =IF($A17="","",N17/MAX(1,$Q$1)) -> 0 | P17: =IF(OR(N17="",$N$5=0),"",N17/$N$5)
A18: =IFERROR(INDEX(_Segéd!$A$2:$A$97,MATCH(7,_Segéd!$B$2:$B$97,0)),"") | B18: =IF($A18="","",SUMIF(Január!$A$5:$A$14,$A18,Január!$B$5:$B$14)) | C18: =IF($A18="","",SUMIF(Február!$A$5:$A$14,$A18,Február!$B$5:$B$14)) | D18: =IF($A18="","",SUMIF(Március!$A$5:$A$14,$A18,Március!$B$5:$B$14)) | E18: =IF($A18="","",SUMIF(Április!$A$5:$A$14,$A18,Április!$B$5:$B$14)) | F18: =IF($A18="","",SUMIF(Május!$A$5:$A$14,$A18,Május!$B$5:$B$14)) | G18: =IF($A18="","",SUMIF(Június!$A$5:$A$14,$A18,Június!$B$5:$B$14)) | H18: =IF($A18="","",SUMIF(Július!$A$5:$A$14,$A18,Július!$B$5:$B$14)) | I18: =IF($A18="","",SUMIF(Augusztus!$A$5:$A$14,$A18,Augusztus!$B$5:$B$14)) | J18: =IF($A18="","",SUMIF(Szeptember!$A$5:$A$14,$A18,Szeptember!$B$5:$B$14)) | K18: =IF($A18="","",SUMIF(Október!$A$5:$A$14,$A18,Október!$B$5:$B$14)) | L18: =IF($A18="","",SUMIF(November!$A$5:$A$14,$A18,November!$B$5:$B$14)) | M18: =IF($A18="","",SUMIF(December!$A$5:$A$14,$A18,December!$B$5:$B$14)) | N18: =IF($A18="","",SUM(B18:M18)) | O18: =IF($A18="","",N18/MAX(1,$Q$1)) | P18: =IF(OR(N18="",$N$5=0),"",N18/$N$5)
A19: =IFERROR(INDEX(_Segéd!$A$2:$A$97,MATCH(8,_Segéd!$B$2:$B$97,0)),"") | B19: =IF($A19="","",SUMIF(Január!$A$5:$A$14,$A19,Január!$B$5:$B$14)) | C19: =IF($A19="","",SUMIF(Február!$A$5:$A$14,$A19,Február!$B$5:$B$14)) | D19: =IF($A19="","",SUMIF(Március!$A$5:$A$14,$A19,Március!$B$5:$B$14)) | E19: =IF($A19="","",SUMIF(Április!$A$5:$A$14,$A19,Április!$B$5:$B$14)) | F19: =IF($A19="","",SUMIF(Május!$A$5:$A$14,$A19,Május!$B$5:$B$14)) | G19: =IF($A19="","",SUMIF(Június!$A$5:$A$14,$A19,Június!$B$5:$B$14)) | H19: =IF($A19="","",SUMIF(Július!$A$5:$A$14,$A19,Július!$B$5:$B$14)) | I19: =IF($A19="","",SUMIF(Augusztus!$A$5:$A$14,$A19,Augusztus!$B$5:$B$14)) | J19: =IF($A19="","",SUMIF(Szeptember!$A$5:$A$14,$A19,Szeptember!$B$5:$B$14)) | K19: =IF($A19="","",SUMIF(Október!$A$5:$A$14,$A19,Október!$B$5:$B$14)) | L19: =IF($A19="","",SUMIF(November!$A$5:$A$14,$A19,November!$B$5:$B$14)) | M19: =IF($A19="","",SUMIF(December!$A$5:$A$14,$A19,December!$B$5:$B$14)) | N19: =IF($A19="","",SUM(B19:M19)) | O19: =IF($A19="","",N19/MAX(1,$Q$1)) | P19: =IF(OR(N19="",$N$5=0),"",N19/$N$5)
A20: =IFERROR(INDEX(_Segéd!$A$2:$A$97,MATCH(9,_Segéd!$B$2:$B$97,0)),"") | B20: =IF($A20="","",SUMIF(Január!$A$5:$A$14,$A20,Január!$B$5:$B$14)) | C20: =IF($A20="","",SUMIF(Február!$A$5:$A$14,$A20,Február!$B$5:$B$14)) | D20: =IF($A20="","",SUMIF(Március!$A$5:$A$14,$A20,Március!$B$5:$B$14)) | E20: =IF($A20="","",SUMIF(Április!$A$5:$A$14,$A20,Április!$B$5:$B$14)) | F20: =IF($A20="","",SUMIF(Május!$A$5:$A$14,$A20,Május!$B$5:$B$14)) | G20: =IF($A20="","",SUMIF(Június!$A$5:$A$14,$A20,Június!$B$5:$B$14)) | H20: =IF($A20="","",SUMIF(Július!$A$5:$A$14,$A20,Július!$B$5:$B$14)) | I20: =IF($A20="","",SUMIF(Augusztus!$A$5:$A$14,$A20,Augusztus!$B$5:$B$14)) | J20: =IF($A20="","",SUMIF(Szeptember!$A$5:$A$14,$A20,Szeptember!$B$5:$B$14)) | K20: =IF($A20="","",SUMIF(Október!$A$5:$A$14,$A20,Október!$B$5:$B$14)) | L20: =IF($A20="","",SUMIF(November!$A$5:$A$14,$A20,November!$B$5:$B$14)) | M20: =IF($A20="","",SUMIF(December!$A$5:$A$14,$A20,December!$B$5:$B$14)) | N20: =IF($A20="","",SUM(B20:M20)) | O20: =IF($A20="","",N20/MAX(1,$Q$1)) | P20: =IF(OR(N20="",$N$5=0),"",N20/$N$5)
A21: =IFERROR(INDEX(_Segéd!$A$2:$A$97,MATCH(10,_Segéd!$B$2:$B$97,0)),"") | B21: =IF($A21="","",SUMIF(Január!$A$5:$A$14,$A21,Január!$B$5:$B$14)) | C21: =IF($A21="","",SUMIF(Február!$A$5:$A$14,$A21,Február!$B$5:$B$14)) | D21: =IF($A21="","",SUMIF(Március!$A$5:$A$14,$A21,Március!$B$5:$B$14)) | E21: =IF($A21="","",SUMIF(Április!$A$5:$A$14,$A21,Április!$B$5:$B$14)) | F21: =IF($A21="","",SUMIF(Május!$A$5:$A$14,$A21,Május!$B$5:$B$14)) | G21: =IF($A21="","",SUMIF(Június!$A$5:$A$14,$A21,Június!$B$5:$B$14)) | H21: =IF($A21="","",SUMIF(Július!$A$5:$A$14,$A21,Július!$B$5:$B$14)) | I21: =IF($A21="","",SUMIF(Augusztus!$A$5:$A$14,$A21,Augusztus!$B$5:$B$14)) | J21: =IF($A21="","",SUMIF(Szeptember!$A$5:$A$14,$A21,Szeptember!$B$5:$B$14)) | K21: =IF($A21="","",SUMIF(Október!$A$5:$A$14,$A21,Október!$B$5:$B$14)) | L21: =IF($A21="","",SUMIF(November!$A$5:$A$14,$A21,November!$B$5:$B$14)) | M21: =IF($A21="","",SUMIF(December!$A$5:$A$14,$A21,December!$B$5:$B$14)) | N21: =IF($A21="","",SUM(B21:M21)) | O21: =IF($A21="","",N21/MAX(1,$Q$1)) | P21: =IF(OR(N21="",$N$5=0),"",N21/$N$5)
A22: =IFERROR(INDEX(_Segéd!$A$2:$A$97,MATCH(11,_Segéd!$B$2:$B$97,0)),"") | B22: =IF($A22="","",SUMIF(Január!$A$5:$A$14,$A22,Január!$B$5:$B$14)) | C22: =IF($A22="","",SUMIF(Február!$A$5:$A$14,$A22,Február!$B$5:$B$14)) | D22: =IF($A22="","",SUMIF(Március!$A$5:$A$14,$A22,Március!$B$5:$B$14)) | E22: =IF($A22="","",SUMIF(Április!$A$5:$A$14,$A22,Április!$B$5:$B$14)) | F22: =IF($A22="","",SUMIF(Május!$A$5:$A$14,$A22,Május!$B$5:$B$14)) | G22: =IF($A22="","",SUMIF(Június!$A$5:$A$14,$A22,Június!$B$5:$B$14)) | H22: =IF($A22="","",SUMIF(Július!$A$5:$A$14,$A22,Július!$B$5:$B$14)) | I22: =IF($A22="","",SUMIF(Augusztus!$A$5:$A$14,$A22,Augusztus!$B$5:$B$14)) | J22: =IF($A22="","",SUMIF(Szeptember!$A$5:$A$14,$A22,Szeptember!$B$5:$B$14)) | K22: =IF($A22="","",SUMIF(Október!$A$5:$A$14,$A22,Október!$B$5:$B$14)) | L22: =IF($A22="","",SUMIF(November!$A$5:$A$14,$A22,November!$B$5:$B$14)) | M22: =IF($A22="","",SUMIF(December!$A$5:$A$14,$A22,December!$B$5:$B$14)) | N22: =IF($A22="","",SUM(B22:M22)) | O22: =IF($A22="","",N22/MAX(1,$Q$1)) | P22: =IF(OR(N22="",$N$5=0),"",N22/$N$5)
A23: =IFERROR(INDEX(_Segéd!$A$2:$A$97,MATCH(12,_Segéd!$B$2:$B$97,0)),"") | B23: =IF($A23="","",SUMIF(Január!$A$5:$A$14,$A23,Január!$B$5:$B$14)) | C23: =IF($A23="","",SUMIF(Február!$A$5:$A$14,$A23,Február!$B$5:$B$14)) | D23: =IF($A23="","",SUMIF(Március!$A$5:$A$14,$A23,Március!$B$5:$B$14)) | E23: =IF($A23="","",SUMIF(Április!$A$5:$A$14,$A23,Április!$B$5:$B$14)) | F23: =IF($A23="","",SUMIF(Május!$A$5:$A$14,$A23,Május!$B$5:$B$14)) | G23: =IF($A23="","",SUMIF(Június!$A$5:$A$14,$A23,Június!$B$5:$B$14)) | H23: =IF($A23="","",SUMIF(Július!$A$5:$A$14,$A23,Július!$B$5:$B$14)) | I23: =IF($A23="","",SUMIF(Augusztus!$A$5:$A$14,$A23,Augusztus!$B$5:$B$14)) | J23: =IF($A23="","",SUMIF(Szeptember!$A$5:$A$14,$A23,Szeptember!$B$5:$B$14)) | K23: =IF($A23="","",SUMIF(Október!$A$5:$A$14,$A23,Október!$B$5:$B$14)) | L23: =IF($A23="","",SUMIF(November!$A$5:$A$14,$A23,November!$B$5:$B$14)) | M23: =IF($A23="","",SUMIF(December!$A$5:$A$14,$A23,December!$B$5:$B$14)) | N23: =IF($A23="","",SUM(B23:M23)) | O23: =IF($A23="","",N23/MAX(1,$Q$1)) | P23: =IF(OR(N23="",$N$5=0),"",N23/$N$5)
A24: 💎 MEGTAKARÍTÁSOK TÉTELENKÉNT | B24: Jan | C24: Feb | D24: Már | E24: Ápr | F24: Máj | G24: Jún | H24: Júl | I24: Aug | J24: Sze | K24: Okt | L24: Nov | M24: Dec | N24: ÉVES | O24: Havi átlag* | P24: Arány
A25: =IFERROR(INDEX(_Segéd!$D$2:$D$121,MATCH(1,_Segéd!$E$2:$E$121,0)),"") -> Vésztartalék | B25: =IF($A25="","",SUMIF(Január!$A$18:$A$27,$A25,Január!$B$18:$B$27)) -> 0 | C25: =IF($A25="","",SUMIF(Február!$A$18:$A$27,$A25,Február!$B$18:$B$27)) -> 0 | D25: =IF($A25="","",SUMIF(Március!$A$18:$A$27,$A25,Március!$B$18:$B$27)) -> 0 | E25: =IF($A25="","",SUMIF(Április!$A$18:$A$27,$A25,Április!$B$18:$B$27)) -> 0 | F25: =IF($A25="","",SUMIF(Május!$A$18:$A$27,$A25,Május!$B$18:$B$27)) -> 0 | G25: =IF($A25="","",SUMIF(Június!$A$18:$A$27,$A25,Június!$B$18:$B$27)) -> 0 | H25: =IF($A25="","",SUMIF(Július!$A$18:$A$27,$A25,Július!$B$18:$B$27)) -> 0 | I25: =IF($A25="","",SUMIF(Augusztus!$A$18:$A$27,$A25,Augusztus!$B$18:$B$27)) -> 0 | J25: =IF($A25="","",SUMIF(Szeptember!$A$18:$A$27,$A25,Szeptember!$B$18:$B$27)) -> 0 | K25: =IF($A25="","",SUMIF(Október!$A$18:$A$27,$A25,Október!$B$18:$B$27)) -> 0 | L25: =IF($A25="","",SUMIF(November!$A$18:$A$27,$A25,November!$B$18:$B$27)) -> 0 | M25: =IF($A25="","",SUMIF(December!$A$18:$A$27,$A25,December!$B$18:$B$27)) -> 0 | N25: =IF($A25="","",SUM(B25:M25)) -> 0 | O25: =IF($A25="","",N25/MAX(1,$Q$1)) -> 0 | P25: =IF(OR(N25="",$N$6=0),"",N25/$N$6)
A26: =IFERROR(INDEX(_Segéd!$D$2:$D$121,MATCH(2,_Segéd!$E$2:$E$121,0)),"") -> Lakástakarékpénztár | B26: =IF($A26="","",SUMIF(Január!$A$18:$A$27,$A26,Január!$B$18:$B$27)) -> 0 | C26: =IF($A26="","",SUMIF(Február!$A$18:$A$27,$A26,Február!$B$18:$B$27)) -> 0 | D26: =IF($A26="","",SUMIF(Március!$A$18:$A$27,$A26,Március!$B$18:$B$27)) -> 0 | E26: =IF($A26="","",SUMIF(Április!$A$18:$A$27,$A26,Április!$B$18:$B$27)) -> 0 | F26: =IF($A26="","",SUMIF(Május!$A$18:$A$27,$A26,Május!$B$18:$B$27)) -> 0 | G26: =IF($A26="","",SUMIF(Június!$A$18:$A$27,$A26,Június!$B$18:$B$27)) -> 0 | H26: =IF($A26="","",SUMIF(Július!$A$18:$A$27,$A26,Július!$B$18:$B$27)) -> 0 | I26: =IF($A26="","",SUMIF(Augusztus!$A$18:$A$27,$A26,Augusztus!$B$18:$B$27)) -> 0 | J26: =IF($A26="","",SUMIF(Szeptember!$A$18:$A$27,$A26,Szeptember!$B$18:$B$27)) -> 0 | K26: =IF($A26="","",SUMIF(Október!$A$18:$A$27,$A26,Október!$B$18:$B$27)) -> 0 | L26: =IF($A26="","",SUMIF(November!$A$18:$A$27,$A26,November!$B$18:$B$27)) -> 0 | M26: =IF($A26="","",SUMIF(December!$A$18:$A$27,$A26,December!$B$18:$B$27)) -> 0 | N26: =IF($A26="","",SUM(B26:M26)) -> 0 | O26: =IF($A26="","",N26/MAX(1,$Q$1)) -> 0 | P26: =IF(OR(N26="",$N$6=0),"",N26/$N$6)
A27: =IFERROR(INDEX(_Segéd!$D$2:$D$121,MATCH(3,_Segéd!$E$2:$E$121,0)),"") -> Általános cél | B27: =IF($A27="","",SUMIF(Január!$A$18:$A$27,$A27,Január!$B$18:$B$27)) -> 0 | C27: =IF($A27="","",SUMIF(Február!$A$18:$A$27,$A27,Február!$B$18:$B$27)) -> 0 | D27: =IF($A27="","",SUMIF(Március!$A$18:$A$27,$A27,Március!$B$18:$B$27)) -> 0 | E27: =IF($A27="","",SUMIF(Április!$A$18:$A$27,$A27,Április!$B$18:$B$27)) -> 0 | F27: =IF($A27="","",SUMIF(Május!$A$18:$A$27,$A27,Május!$B$18:$B$27)) -> 0 | G27: =IF($A27="","",SUMIF(Június!$A$18:$A$27,$A27,Június!$B$18:$B$27)) -> 0 | H27: =IF($A27="","",SUMIF(Július!$A$18:$A$27,$A27,Július!$B$18:$B$27)) -> 0 | I27: =IF($A27="","",SUMIF(Augusztus!$A$18:$A$27,$A27,Augusztus!$B$18:$B$27)) -> 0 | J27: =IF($A27="","",SUMIF(Szeptember!$A$18:$A$27,$A27,Szeptember!$B$18:$B$27)) -> 0 | K27: =IF($A27="","",SUMIF(Október!$A$18:$A$27,$A27,Október!$B$18:$B$27)) -> 0 | L27: =IF($A27="","",SUMIF(November!$A$18:$A$27,$A27,November!$B$18:$B$27)) -> 0 | M27: =IF($A27="","",SUMIF(December!$A$18:$A$27,$A27,December!$B$18:$B$27)) -> 0 | N27: =IF($A27="","",SUM(B27:M27)) -> 0 | O27: =IF($A27="","",N27/MAX(1,$Q$1)) -> 0 | P27: =IF(OR(N27="",$N$6=0),"",N27/$N$6)
A28: =IFERROR(INDEX(_Segéd!$D$2:$D$121,MATCH(4,_Segéd!$E$2:$E$121,0)),"") -> Hosszú távú (min. 10 éves, általános célú) | B28: =IF($A28="","",SUMIF(Január!$A$18:$A$27,$A28,Január!$B$18:$B$27)) -> 0 | C28: =IF($A28="","",SUMIF(Február!$A$18:$A$27,$A28,Február!$B$18:$B$27)) -> 0 | D28: =IF($A28="","",SUMIF(Március!$A$18:$A$27,$A28,Március!$B$18:$B$27)) -> 0 | E28: =IF($A28="","",SUMIF(Április!$A$18:$A$27,$A28,Április!$B$18:$B$27)) -> 0 | F28: =IF($A28="","",SUMIF(Május!$A$18:$A$27,$A28,Május!$B$18:$B$27)) -> 0 | G28: =IF($A28="","",SUMIF(Június!$A$18:$A$27,$A28,Június!$B$18:$B$27)) -> 0 | H28: =IF($A28="","",SUMIF(Július!$A$18:$A$27,$A28,Július!$B$18:$B$27)) -> 0 | I28: =IF($A28="","",SUMIF(Augusztus!$A$18:$A$27,$A28,Augusztus!$B$18:$B$27)) -> 0 | J28: =IF($A28="","",SUMIF(Szeptember!$A$18:$A$27,$A28,Szeptember!$B$18:$B$27)) -> 0 | K28: =IF($A28="","",SUMIF(Október!$A$18:$A$27,$A28,Október!$B$18:$B$27)) -> 0 | L28: =IF($A28="","",SUMIF(November!$A$18:$A$27,$A28,November!$B$18:$B$27)) -> 0 | M28: =IF($A28="","",SUMIF(December!$A$18:$A$27,$A28,December!$B$18:$B$27)) -> 0 | N28: =IF($A28="","",SUM(B28:M28)) -> 0 | O28: =IF($A28="","",N28/MAX(1,$Q$1)) -> 0 | P28: =IF(OR(N28="",$N$6=0),"",N28/$N$6)
A29: =IFERROR(INDEX(_Segéd!$D$2:$D$121,MATCH(5,_Segéd!$E$2:$E$121,0)),"") -> Hosszú távú (min. 10 éves, lakás célú) | B29: =IF($A29="","",SUMIF(Január!$A$18:$A$27,$A29,Január!$B$18:$B$27)) -> 0 | C29: =IF($A29="","",SUMIF(Február!$A$18:$A$27,$A29,Február!$B$18:$B$27)) -> 0 | D29: =IF($A29="","",SUMIF(Március!$A$18:$A$27,$A29,Március!$B$18:$B$27)) -> 0 | E29: =IF($A29="","",SUMIF(Április!$A$18:$A$27,$A29,Április!$B$18:$B$27)) -> 0 | F29: =IF($A29="","",SUMIF(Május!$A$18:$A$27,$A29,Május!$B$18:$B$27)) -> 0 | G29: =IF($A29="","",SUMIF(Június!$A$18:$A$27,$A29,Június!$B$18:$B$27)) -> 0 | H29: =IF($A29="","",SUMIF(Július!$A$18:$A$27,$A29,Július!$B$18:$B$27)) -> 0 | I29: =IF($A29="","",SUMIF(Augusztus!$A$18:$A$27,$A29,Augusztus!$B$18:$B$27)) -> 0 | J29: =IF($A29="","",SUMIF(Szeptember!$A$18:$A$27,$A29,Szeptember!$B$18:$B$27)) -> 0 | K29: =IF($A29="","",SUMIF(Október!$A$18:$A$27,$A29,Október!$B$18:$B$27)) -> 0 | L29: =IF($A29="","",SUMIF(November!$A$18:$A$27,$A29,November!$B$18:$B$27)) -> 0 | M29: =IF($A29="","",SUMIF(December!$A$18:$A$27,$A29,December!$B$18:$B$27)) -> 0 | N29: =IF($A29="","",SUM(B29:M29)) -> 0 | O29: =IF($A29="","",N29/MAX(1,$Q$1)) -> 0 | P29: =IF(OR(N29="",$N$6=0),"",N29/$N$6)
A30: =IFERROR(INDEX(_Segéd!$D$2:$D$121,MATCH(6,_Segéd!$E$2:$E$121,0)),"") -> Hosszú távú (min. 10 éves, gyermek jövője célú) | B30: =IF($A30="","",SUMIF(Január!$A$18:$A$27,$A30,Január!$B$18:$B$27)) -> 0 | C30: =IF($A30="","",SUMIF(Február!$A$18:$A$27,$A30,Február!$B$18:$B$27)) -> 0 | D30: =IF($A30="","",SUMIF(Március!$A$18:$A$27,$A30,Március!$B$18:$B$27)) -> 0 | E30: =IF($A30="","",SUMIF(Április!$A$18:$A$27,$A30,Április!$B$18:$B$27)) -> 0 | F30: =IF($A30="","",SUMIF(Május!$A$18:$A$27,$A30,Május!$B$18:$B$27)) -> 0 | G30: =IF($A30="","",SUMIF(Június!$A$18:$A$27,$A30,Június!$B$18:$B$27)) -> 0 | H30: =IF($A30="","",SUMIF(Július!$A$18:$A$27,$A30,Július!$B$18:$B$27)) -> 0 | I30: =IF($A30="","",SUMIF(Augusztus!$A$18:$A$27,$A30,Augusztus!$B$18:$B$27)) -> 0 | J30: =IF($A30="","",SUMIF(Szeptember!$A$18:$A$27,$A30,Szeptember!$B$18:$B$27)) -> 0 | K30: =IF($A30="","",SUMIF(Október!$A$18:$A$27,$A30,Október!$B$18:$B$27)) -> 0 | L30: =IF($A30="","",SUMIF(November!$A$18:$A$27,$A30,November!$B$18:$B$27)) -> 0 | M30: =IF($A30="","",SUMIF(December!$A$18:$A$27,$A30,December!$B$18:$B$27)) -> 0 | N30: =IF($A30="","",SUM(B30:M30)) -> 0 | O30: =IF($A30="","",N30/MAX(1,$Q$1)) -> 0 | P30: =IF(OR(N30="",$N$6=0),"",N30/$N$6)
A31: =IFERROR(INDEX(_Segéd!$D$2:$D$121,MATCH(7,_Segéd!$E$2:$E$121,0)),"") -> Hosszú távú (min. 15 éves, nyugdíj célú) | B31: =IF($A31="","",SUMIF(Január!$A$18:$A$27,$A31,Január!$B$18:$B$27)) -> 0 | C31: =IF($A31="","",SUMIF(Február!$A$18:$A$27,$A31,Február!$B$18:$B$27)) -> 0 | D31: =IF($A31="","",SUMIF(Március!$A$18:$A$27,$A31,Március!$B$18:$B$27)) -> 0 | E31: =IF($A31="","",SUMIF(Április!$A$18:$A$27,$A31,Április!$B$18:$B$27)) -> 0 | F31: =IF($A31="","",SUMIF(Május!$A$18:$A$27,$A31,Május!$B$18:$B$27)) -> 0 | G31: =IF($A31="","",SUMIF(Június!$A$18:$A$27,$A31,Június!$B$18:$B$27)) -> 0 | H31: =IF($A31="","",SUMIF(Július!$A$18:$A$27,$A31,Július!$B$18:$B$27)) -> 0 | I31: =IF($A31="","",SUMIF(Augusztus!$A$18:$A$27,$A31,Augusztus!$B$18:$B$27)) -> 0 | J31: =IF($A31="","",SUMIF(Szeptember!$A$18:$A$27,$A31,Szeptember!$B$18:$B$27)) -> 0 | K31: =IF($A31="","",SUMIF(Október!$A$18:$A$27,$A31,Október!$B$18:$B$27)) -> 0 | L31: =IF($A31="","",SUMIF(November!$A$18:$A$27,$A31,November!$B$18:$B$27)) -> 0 | M31: =IF($A31="","",SUMIF(December!$A$18:$A$27,$A31,December!$B$18:$B$27)) -> 0 | N31: =IF($A31="","",SUM(B31:M31)) -> 0 | O31: =IF($A31="","",N31/MAX(1,$Q$1)) -> 0 | P31: =IF(OR(N31="",$N$6=0),"",N31/$N$6)
A32: =IFERROR(INDEX(_Segéd!$D$2:$D$121,MATCH(8,_Segéd!$E$2:$E$121,0)),"") -> Nyugdíjbiztosítás | B32: =IF($A32="","",SUMIF(Január!$A$18:$A$27,$A32,Január!$B$18:$B$27)) -> 0 | C32: =IF($A32="","",SUMIF(Február!$A$18:$A$27,$A32,Február!$B$18:$B$27)) -> 0 | D32: =IF($A32="","",SUMIF(Március!$A$18:$A$27,$A32,Március!$B$18:$B$27)) -> 0 | E32: =IF($A32="","",SUMIF(Április!$A$18:$A$27,$A32,Április!$B$18:$B$27)) -> 0 | F32: =IF($A32="","",SUMIF(Május!$A$18:$A$27,$A32,Május!$B$18:$B$27)) -> 0 | G32: =IF($A32="","",SUMIF(Június!$A$18:$A$27,$A32,Június!$B$18:$B$27)) -> 0 | H32: =IF($A32="","",SUMIF(Július!$A$18:$A$27,$A32,Július!$B$18:$B$27)) -> 0 | I32: =IF($A32="","",SUMIF(Augusztus!$A$18:$A$27,$A32,Augusztus!$B$18:$B$27)) -> 0 | J32: =IF($A32="","",SUMIF(Szeptember!$A$18:$A$27,$A32,Szeptember!$B$18:$B$27)) -> 0 | K32: =IF($A32="","",SUMIF(Október!$A$18:$A$27,$A32,Október!$B$18:$B$27)) -> 0 | L32: =IF($A32="","",SUMIF(November!$A$18:$A$27,$A32,November!$B$18:$B$27)) -> 0 | M32: =IF($A32="","",SUMIF(December!$A$18:$A$27,$A32,December!$B$18:$B$27)) -> 0 | N32: =IF($A32="","",SUM(B32:M32)) -> 0 | O32: =IF($A32="","",N32/MAX(1,$Q$1)) -> 0 | P32: =IF(OR(N32="",$N$6=0),"",N32/$N$6)
A33: =IFERROR(INDEX(_Segéd!$D$2:$D$121,MATCH(9,_Segéd!$E$2:$E$121,0)),"") | B33: =IF($A33="","",SUMIF(Január!$A$18:$A$27,$A33,Január!$B$18:$B$27)) | C33: =IF($A33="","",SUMIF(Február!$A$18:$A$27,$A33,Február!$B$18:$B$27)) | D33: =IF($A33="","",SUMIF(Március!$A$18:$A$27,$A33,Március!$B$18:$B$27)) | E33: =IF($A33="","",SUMIF(Április!$A$18:$A$27,$A33,Április!$B$18:$B$27)) | F33: =IF($A33="","",SUMIF(Május!$A$18:$A$27,$A33,Május!$B$18:$B$27)) | G33: =IF($A33="","",SUMIF(Június!$A$18:$A$27,$A33,Június!$B$18:$B$27)) | H33: =IF($A33="","",SUMIF(Július!$A$18:$A$27,$A33,Július!$B$18:$B$27)) | I33: =IF($A33="","",SUMIF(Augusztus!$A$18:$A$27,$A33,Augusztus!$B$18:$B$27)) | J33: =IF($A33="","",SUMIF(Szeptember!$A$18:$A$27,$A33,Szeptember!$B$18:$B$27)) | K33: =IF($A33="","",SUMIF(Október!$A$18:$A$27,$A33,Október!$B$18:$B$27)) | L33: =IF($A33="","",SUMIF(November!$A$18:$A$27,$A33,November!$B$18:$B$27)) | M33: =IF($A33="","",SUMIF(December!$A$18:$A$27,$A33,December!$B$18:$B$27)) | N33: =IF($A33="","",SUM(B33:M33)) | O33: =IF($A33="","",N33/MAX(1,$Q$1)) | P33: =IF(OR(N33="",$N$6=0),"",N33/$N$6)
A34: =IFERROR(INDEX(_Segéd!$D$2:$D$121,MATCH(10,_Segéd!$E$2:$E$121,0)),"") | B34: =IF($A34="","",SUMIF(Január!$A$18:$A$27,$A34,Január!$B$18:$B$27)) | C34: =IF($A34="","",SUMIF(Február!$A$18:$A$27,$A34,Február!$B$18:$B$27)) | D34: =IF($A34="","",SUMIF(Március!$A$18:$A$27,$A34,Március!$B$18:$B$27)) | E34: =IF($A34="","",SUMIF(Április!$A$18:$A$27,$A34,Április!$B$18:$B$27)) | F34: =IF($A34="","",SUMIF(Május!$A$18:$A$27,$A34,Május!$B$18:$B$27)) | G34: =IF($A34="","",SUMIF(Június!$A$18:$A$27,$A34,Június!$B$18:$B$27)) | H34: =IF($A34="","",SUMIF(Július!$A$18:$A$27,$A34,Július!$B$18:$B$27)) | I34: =IF($A34="","",SUMIF(Augusztus!$A$18:$A$27,$A34,Augusztus!$B$18:$B$27)) | J34: =IF($A34="","",SUMIF(Szeptember!$A$18:$A$27,$A34,Szeptember!$B$18:$B$27)) | K34: =IF($A34="","",SUMIF(Október!$A$18:$A$27,$A34,Október!$B$18:$B$27)) | L34: =IF($A34="","",SUMIF(November!$A$18:$A$27,$A34,November!$B$18:$B$27)) | M34: =IF($A34="","",SUMIF(December!$A$18:$A$27,$A34,December!$B$18:$B$27)) | N34: =IF($A34="","",SUM(B34:M34)) | O34: =IF($A34="","",N34/MAX(1,$Q$1)) | P34: =IF(OR(N34="",$N$6=0),"",N34/$N$6)
A35: =IFERROR(INDEX(_Segéd!$D$2:$D$121,MATCH(11,_Segéd!$E$2:$E$121,0)),"") | B35: =IF($A35="","",SUMIF(Január!$A$18:$A$27,$A35,Január!$B$18:$B$27)) | C35: =IF($A35="","",SUMIF(Február!$A$18:$A$27,$A35,Február!$B$18:$B$27)) | D35: =IF($A35="","",SUMIF(Március!$A$18:$A$27,$A35,Március!$B$18:$B$27)) | E35: =IF($A35="","",SUMIF(Április!$A$18:$A$27,$A35,Április!$B$18:$B$27)) | F35: =IF($A35="","",SUMIF(Május!$A$18:$A$27,$A35,Május!$B$18:$B$27)) | G35: =IF($A35="","",SUMIF(Június!$A$18:$A$27,$A35,Június!$B$18:$B$27)) | H35: =IF($A35="","",SUMIF(Július!$A$18:$A$27,$A35,Július!$B$18:$B$27)) | I35: =IF($A35="","",SUMIF(Augusztus!$A$18:$A$27,$A35,Augusztus!$B$18:$B$27)) | J35: =IF($A35="","",SUMIF(Szeptember!$A$18:$A$27,$A35,Szeptember!$B$18:$B$27)) | K35: =IF($A35="","",SUMIF(Október!$A$18:$A$27,$A35,Október!$B$18:$B$27)) | L35: =IF($A35="","",SUMIF(November!$A$18:$A$27,$A35,November!$B$18:$B$27)) | M35: =IF($A35="","",SUMIF(December!$A$18:$A$27,$A35,December!$B$18:$B$27)) | N35: =IF($A35="","",SUM(B35:M35)) | O35: =IF($A35="","",N35/MAX(1,$Q$1)) | P35: =IF(OR(N35="",$N$6=0),"",N35/$N$6)
A36: =IFERROR(INDEX(_Segéd!$D$2:$D$121,MATCH(12,_Segéd!$E$2:$E$121,0)),"") | B36: =IF($A36="","",SUMIF(Január!$A$18:$A$27,$A36,Január!$B$18:$B$27)) | C36: =IF($A36="","",SUMIF(Február!$A$18:$A$27,$A36,Február!$B$18:$B$27)) | D36: =IF($A36="","",SUMIF(Március!$A$18:$A$27,$A36,Március!$B$18:$B$27)) | E36: =IF($A36="","",SUMIF(Április!$A$18:$A$27,$A36,Április!$B$18:$B$27)) | F36: =IF($A36="","",SUMIF(Május!$A$18:$A$27,$A36,Május!$B$18:$B$27)) | G36: =IF($A36="","",SUMIF(Június!$A$18:$A$27,$A36,Június!$B$18:$B$27)) | H36: =IF($A36="","",SUMIF(Július!$A$18:$A$27,$A36,Július!$B$18:$B$27)) | I36: =IF($A36="","",SUMIF(Augusztus!$A$18:$A$27,$A36,Augusztus!$B$18:$B$27)) | J36: =IF($A36="","",SUMIF(Szeptember!$A$18:$A$27,$A36,Szeptember!$B$18:$B$27)) | K36: =IF($A36="","",SUMIF(Október!$A$18:$A$27,$A36,Október!$B$18:$B$27)) | L36: =IF($A36="","",SUMIF(November!$A$18:$A$27,$A36,November!$B$18:$B$27)) | M36: =IF($A36="","",SUMIF(December!$A$18:$A$27,$A36,December!$B$18:$B$27)) | N36: =IF($A36="","",SUM(B36:M36)) | O36: =IF($A36="","",N36/MAX(1,$Q$1)) | P36: =IF(OR(N36="",$N$6=0),"",N36/$N$6)
A37: =IFERROR(INDEX(_Segéd!$D$2:$D$121,MATCH(13,_Segéd!$E$2:$E$121,0)),"") | B37: =IF($A37="","",SUMIF(Január!$A$18:$A$27,$A37,Január!$B$18:$B$27)) | C37: =IF($A37="","",SUMIF(Február!$A$18:$A$27,$A37,Február!$B$18:$B$27)) | D37: =IF($A37="","",SUMIF(Március!$A$18:$A$27,$A37,Március!$B$18:$B$27)) | E37: =IF($A37="","",SUMIF(Április!$A$18:$A$27,$A37,Április!$B$18:$B$27)) | F37: =IF($A37="","",SUMIF(Május!$A$18:$A$27,$A37,Május!$B$18:$B$27)) | G37: =IF($A37="","",SUMIF(Június!$A$18:$A$27,$A37,Június!$B$18:$B$27)) | H37: =IF($A37="","",SUMIF(Július!$A$18:$A$27,$A37,Július!$B$18:$B$27)) | I37: =IF($A37="","",SUMIF(Augusztus!$A$18:$A$27,$A37,Augusztus!$B$18:$B$27)) | J37: =IF($A37="","",SUMIF(Szeptember!$A$18:$A$27,$A37,Szeptember!$B$18:$B$27)) | K37: =IF($A37="","",SUMIF(Október!$A$18:$A$27,$A37,Október!$B$18:$B$27)) | L37: =IF($A37="","",SUMIF(November!$A$18:$A$27,$A37,November!$B$18:$B$27)) | M37: =IF($A37="","",SUMIF(December!$A$18:$A$27,$A37,December!$B$18:$B$27)) | N37: =IF($A37="","",SUM(B37:M37)) | O37: =IF($A37="","",N37/MAX(1,$Q$1)) | P37: =IF(OR(N37="",$N$6=0),"",N37/$N$6)
A38: =IFERROR(INDEX(_Segéd!$D$2:$D$121,MATCH(14,_Segéd!$E$2:$E$121,0)),"") | B38: =IF($A38="","",SUMIF(Január!$A$18:$A$27,$A38,Január!$B$18:$B$27)) | C38: =IF($A38="","",SUMIF(Február!$A$18:$A$27,$A38,Február!$B$18:$B$27)) | D38: =IF($A38="","",SUMIF(Március!$A$18:$A$27,$A38,Március!$B$18:$B$27)) | E38: =IF($A38="","",SUMIF(Április!$A$18:$A$27,$A38,Április!$B$18:$B$27)) | F38: =IF($A38="","",SUMIF(Május!$A$18:$A$27,$A38,Május!$B$18:$B$27)) | G38: =IF($A38="","",SUMIF(Június!$A$18:$A$27,$A38,Június!$B$18:$B$27)) | H38: =IF($A38="","",SUMIF(Július!$A$18:$A$27,$A38,Július!$B$18:$B$27)) | I38: =IF($A38="","",SUMIF(Augusztus!$A$18:$A$27,$A38,Augusztus!$B$18:$B$27)) | J38: =IF($A38="","",SUMIF(Szeptember!$A$18:$A$27,$A38,Szeptember!$B$18:$B$27)) | K38: =IF($A38="","",SUMIF(Október!$A$18:$A$27,$A38,Október!$B$18:$B$27)) | L38: =IF($A38="","",SUMIF(November!$A$18:$A$27,$A38,November!$B$18:$B$27)) | M38: =IF($A38="","",SUMIF(December!$A$18:$A$27,$A38,December!$B$18:$B$27)) | N38: =IF($A38="","",SUM(B38:M38)) | O38: =IF($A38="","",N38/MAX(1,$Q$1)) | P38: =IF(OR(N38="",$N$6=0),"",N38/$N$6)
A39: ❤️ KIADÁSOK KATEGÓRIÁNKÉNT | B39: Jan | C39: Feb | D39: Már | E39: Ápr | F39: Máj | G39: Jún | H39: Júl | I39: Aug | J39: Sze | K39: Okt | L39: Nov | M39: Dec | N39: ÉVES | O39: Havi átlag* | P39: Arány
A40: Lakhatás | B40: =Január!C35 -> 0 | C40: =Február!C35 -> 0 | D40: =Március!C35 -> 0 | E40: =Április!C35 -> 0 | F40: =Május!C35 -> 0 | G40: =Június!C35 -> 0 | H40: =Július!C35 -> 0 | I40: =Augusztus!C35 -> 0 | J40: =Szeptember!C35 -> 0 | K40: =Október!C35 -> 0 | L40: =November!C35 -> 0 | M40: =December!C35 -> 0 | N40: =SUM(B40:M40) -> 0 | O40: =N40/MAX(1,$Q$1) -> 0 | P40: =IF(OR(N40="",$N$7=0),"",N40/$N$7)
A41: Étkezés, bevásárlás | B41: =Január!C42 -> 0 | C41: =Február!C42 -> 0 | D41: =Március!C42 -> 0 | E41: =Április!C42 -> 0 | F41: =Május!C42 -> 0 | G41: =Június!C42 -> 0 | H41: =Július!C42 -> 0 | I41: =Augusztus!C42 -> 0 | J41: =Szeptember!C42 -> 0 | K41: =Október!C42 -> 0 | L41: =November!C42 -> 0 | M41: =December!C42 -> 0 | N41: =SUM(B41:M41) -> 0 | O41: =N41/MAX(1,$Q$1) -> 0 | P41: =IF(OR(N41="",$N$7=0),"",N41/$N$7)
...

Sheet Január
A1: =" 💰 HAVI KÖLTSÉGVETÉS — "&UPPER("Január")&" "&'📊 Éves Összesítő'!$B$2 -> 💰 HAVI KÖLTSÉGVETÉS — JANUÁR 2026
A2: Kategória / Megnevezés | B2: Összeg (Ft) | C2: Összesítő (Ft) | D2: Tervezett (Ft) | E2: Eltérés a tervtől (− = rossz) | F2: Arány
A3: 💚 BEVÉTELEK
A4: Munkából származó bevétel
A5: Munkabér 1 (pl. saját) | E5: =IF(D5=0,"",B5-D5) | F5: =IF(OR($C$16=0,B5=""),"",B5/$C$16)
A6: Munkabér 2 (pl. partner) | E6: =IF(D6=0,"",B6-D6) | F6: =IF(OR($C$16=0,B6=""),"",B6/$C$16)
A7: Vállalkozói bevétel | E7: =IF(D7=0,"",B7-D7) | F7: =IF(OR($C$16=0,B7=""),"",B7/$C$16)
E8: =IF(D8=0,"",B8-D8) | F8: =IF(OR($C$16=0,B8=""),"",B8/$C$16)
A9: ∑ Munkából származó bevétel | C9: =SUM(B5:B8) -> 0 | D9: =SUM(D5:D8) -> 0 | E9: =IF(D9=0,"",C9-D9) | F9: =IF(OR($C$16=0,C9=""),"",C9/$C$16)
A10: Egyéb bevétel
A11: CSED / GYED / GYES | E11: =IF(D11=0,"",B11-D11) | F11: =IF(OR($C$16=0,B11=""),"",B11/$C$16)
A12: Családi pótlék | E12: =IF(D12=0,"",B12-D12) | F12: =IF(OR($C$16=0,B12=""),"",B12/$C$16)
A13: Egyéb (lakáskiadás, bónusz stb.) | E13: =IF(D13=0,"",B13-D13) | F13: =IF(OR($C$16=0,B13=""),"",B13/$C$16)
E14: =IF(D14=0,"",B14-D14) | F14: =IF(OR($C$16=0,B14=""),"",B14/$C$16)
A15: ∑ Egyéb bevétel | C15: =SUM(B11:B14) -> 0 | D15: =SUM(D11:D14) -> 0 | E15: =IF(D15=0,"",C15-D15) | F15: =IF(OR($C$16=0,C15=""),"",C15/$C$16)
A16: ÖSSZESEN: 💚 BEVÉTELEK | C16: =C9+C15 -> 0 | D16: =D9+D15 -> 0 | E16: =IF(D16=0,"",C16-D16) | F16: =IF($C$16=0,"",1)
A17: 💎 MEGTAKARÍTÁSOK
A18: Vésztartalék | E18: =IF(D18=0,"",B18-D18) | F18: =IF(OR($C$28=0,B18=""),"",B18/$C$28)
A19: Lakástakarékpénztár | E19: =IF(D19=0,"",B19-D19) | F19: =IF(OR($C$28=0,B19=""),"",B19/$C$28)
A20: Általános cél | E20: =IF(D20=0,"",B20-D20) | F20: =IF(OR($C$28=0,B20=""),"",B20/$C$28)
A21: Hosszú távú (min. 10 éves, általános célú) | E21: =IF(D21=0,"",B21-D21) | F21: =IF(OR($C$28=0,B21=""),"",B21/$C$28)
A22: Hosszú távú (min. 10 éves, lakás célú) | E22: =IF(D22=0,"",B22-D22) | F22: =IF(OR($C$28=0,B22=""),"",B22/$C$28)
A23: Hosszú távú (min. 10 éves, gyermek jövője célú) | E23: =IF(D23=0,"",B23-D23) | F23: =IF(OR($C$28=0,B23=""),"",B23/$C$28)
A24: Hosszú távú (min. 15 éves, nyugdíj célú) | E24: =IF(D24=0,"",B24-D24) | F24: =IF(OR($C$28=0,B24=""),"",B24/$C$28)
A25: Nyugdíjbiztosítás | E25: =IF(D25=0,"",B25-D25) | F25: =IF(OR($C$28=0,B25=""),"",B25/$C$28)
E26: =IF(D26=0,"",B26-D26) | F26: =IF(OR($C$28=0,B26=""),"",B26/$C$28)
E27: =IF(D27=0,"",B27-D27) | F27: =IF(OR($C$28=0,B27=""),"",B27/$C$28)
A28: ÖSSZESEN: 💎 MEGTAKARÍTÁSOK | C28: =SUM(B18:B27) -> 0 | D28: =SUM(D18:D27) -> 0 | E28: =IF(D28=0,"",C28-D28) | F28: =IF($C$16=0,"",C28/$C$16)
A29: ❤️ KIADÁSOK
A30: Lakhatás
A31: Albérleti díj / lakáshitel | E31: =IF(D31=0,"",D31-B31) | F31: =IF(OR($C$118=0,B31=""),"",B31/$C$118)
A32: Rezsi (közművek, közös költség) | E32: =IF(D32=0,"",D32-B32) | F32: =IF(OR($C$118=0,B32=""),"",B32/$C$118)
A33: Telefon, internet, digitális előfizetések | E33: =IF(D33=0,"",D33-B33) | F33: =IF(OR($C$118=0,B33=""),"",B33/$C$118)
E34: =IF(D34=0,"",D34-B34) | F34: =IF(OR($C$118=0,B34=""),"",B34/$C$118)
A35: ∑ Lakhatás | C35: =SUM(B31:B34) -> 0 | D35: =SUM(D31:D34) -> 0 | E35: =IF(D35=0,"",D35-C35) | F35: =IF(OR($C$118=0,C35=""),"",C35/$C$118)
A36: Étkezés, bevásárlás
A37: Nagybevásárlások | E37: =IF(D37=0,"",D37-B37) | F37: =IF(OR($C$118=0,B37=""),"",B37/$C$118)
A38: Drogéria | E38: =IF(D38=0,"",D38-B38) | F38: =IF(OR($C$118=0,B38=""),"",B38/$C$118)
A39: Ételrendelés | E39: =IF(D39=0,"",D39-B39) | F39: =IF(OR($C$118=0,B39=""),"",B39/$C$118)
A40: Egyéb élelmiszer, bevásárlás | E40: =IF(D40=0,"",D40-B40) | F40: =IF(OR($C$118=0,B40=""),"",B40/$C$118)
...

Sheet Február
A1: =" 💰 HAVI KÖLTSÉGVETÉS — "&UPPER("Február")&" "&'📊 Éves Összesítő'!$B$2 -> 💰 HAVI KÖLTSÉGVETÉS — FEBRUÁR 2026
A2: Kategória / Megnevezés | B2: Összeg (Ft) | C2: Összesítő (Ft) | D2: Tervezett (Ft) | E2: Eltérés a tervtől (− = rossz) | F2: Arány
A3: 💚 BEVÉTELEK
A4: Munkából származó bevétel
A5: =IF(Január!A5="","",Január!A5) -> Munkabér 1 (pl. saját) | E5: =IF(D5=0,"",B5-D5) | F5: =IF(OR($C$16=0,B5=""),"",B5/$C$16)
A6: =IF(Január!A6="","",Január!A6) -> Munkabér 2 (pl. partner) | E6: =IF(D6=0,"",B6-D6) | F6: =IF(OR($C$16=0,B6=""),"",B6/$C$16)
A7: =IF(Január!A7="","",Január!A7) -> Vállalkozói bevétel | E7: =IF(D7=0,"",B7-D7) | F7: =IF(OR($C$16=0,B7=""),"",B7/$C$16)
A8: =IF(Január!A8="","",Január!A8) | E8: =IF(D8=0,"",B8-D8) | F8: =IF(OR($C$16=0,B8=""),"",B8/$C$16)
A9: ∑ Munkából származó bevétel | C9: =SUM(B5:B8) -> 0 | D9: =SUM(D5:D8) -> 0 | E9: =IF(D9=0,"",C9-D9) | F9: =IF(OR($C$16=0,C9=""),"",C9/$C$16)
A10: Egyéb bevétel
A11: =IF(Január!A11="","",Január!A11) -> CSED / GYED / GYES | E11: =IF(D11=0,"",B11-D11) | F11: =IF(OR($C$16=0,B11=""),"",B11/$C$16)
A12: =IF(Január!A12="","",Január!A12) -> Családi pótlék | E12: =IF(D12=0,"",B12-D12) | F12: =IF(OR($C$16=0,B12=""),"",B12/$C$16)
A13: =IF(Január!A13="","",Január!A13) -> Egyéb (lakáskiadás, bónusz stb.) | E13: =IF(D13=0,"",B13-D13) | F13: =IF(OR($C$16=0,B13=""),"",B13/$C$16)
A14: =IF(Január!A14="","",Január!A14) | E14: =IF(D14=0,"",B14-D14) | F14: =IF(OR($C$16=0,B14=""),"",B14/$C$16)
A15: ∑ Egyéb bevétel | C15: =SUM(B11:B14) -> 0 | D15: =SUM(D11:D14) -> 0 | E15: =IF(D15=0,"",C15-D15) | F15: =IF(OR($C$16=0,C15=""),"",C15/$C$16)
A16: ÖSSZESEN: 💚 BEVÉTELEK | C16: =C9+C15 -> 0 | D16: =D9+D15 -> 0 | E16: =IF(D16=0,"",C16-D16) | F16: =IF($C$16=0,"",1)
A17: 💎 MEGTAKARÍTÁSOK
A18: =IF(Január!A18="","",Január!A18) -> Vésztartalék | E18: =IF(D18=0,"",B18-D18) | F18: =IF(OR($C$28=0,B18=""),"",B18/$C$28)
A19: =IF(Január!A19="","",Január!A19) -> Lakástakarékpénztár | E19: =IF(D19=0,"",B19-D19) | F19: =IF(OR($C$28=0,B19=""),"",B19/$C$28)
A20: =IF(Január!A20="","",Január!A20) -> Általános cél | E20: =IF(D20=0,"",B20-D20) | F20: =IF(OR($C$28=0,B20=""),"",B20/$C$28)
A21: =IF(Január!A21="","",Január!A21) -> Hosszú távú (min. 10 éves, általános célú) | E21: =IF(D21=0,"",B21-D21) | F21: =IF(OR($C$28=0,B21=""),"",B21/$C$28)
A22: =IF(Január!A22="","",Január!A22) -> Hosszú távú (min. 10 éves, lakás célú) | E22: =IF(D22=0,"",B22-D22) | F22: =IF(OR($C$28=0,B22=""),"",B22/$C$28)
A23: =IF(Január!A23="","",Január!A23) -> Hosszú távú (min. 10 éves, gyermek jövője célú) | E23: =IF(D23=0,"",B23-D23) | F23: =IF(OR($C$28=0,B23=""),"",B23/$C$28)
A24: =IF(Január!A24="","",Január!A24) -> Hosszú távú (min. 15 éves, nyugdíj célú) | E24: =IF(D24=0,"",B24-D24) | F24: =IF(OR($C$28=0,B24=""),"",B24/$C$28)
A25: =IF(Január!A25="","",Január!A25) -> Nyugdíjbiztosítás | E25: =IF(D25=0,"",B25-D25) | F25: =IF(OR($C$28=0,B25=""),"",B25/$C$28)
A26: =IF(Január!A26="","",Január!A26) | E26: =IF(D26=0,"",B26-D26) | F26: =IF(OR($C$28=0,B26=""),"",B26/$C$28)
A27: =IF(Január!A27="","",Január!A27) | E27: =IF(D27=0,"",B27-D27) | F27: =IF(OR($C$28=0,B27=""),"",B27/$C$28)
A28: ÖSSZESEN: 💎 MEGTAKARÍTÁSOK | C28: =SUM(B18:B27) -> 0 | D28: =SUM(D18:D27) -> 0 | E28: =IF(D28=0,"",C28-D28) | F28: =IF($C$16=0,"",C28/$C$16)
A29: ❤️ KIADÁSOK
A30: Lakhatás
A31: =IF(Január!A31="","",Január!A31) -> Albérleti díj / lakáshitel | E31: =IF(D31=0,"",D31-B31) | F31: =IF(OR($C$118=0,B31=""),"",B31/$C$118)
A32: =IF(Január!A32="","",Január!A32) -> Rezsi (közművek, közös költség) | E32: =IF(D32=0,"",D32-B32) | F32: =IF(OR($C$118=0,B32=""),"",B32/$C$118)
A33: =IF(Január!A33="","",Január!A33) -> Telefon, internet, digitális előfizetések | E33: =IF(D33=0,"",D33-B33) | F33: =IF(OR($C$118=0,B33=""),"",B33/$C$118)
A34: =IF(Január!A34="","",Január!A34) | E34: =IF(D34=0,"",D34-B34) | F34: =IF(OR($C$118=0,B34=""),"",B34/$C$118)
A35: ∑ Lakhatás | C35: =SUM(B31:B34) -> 0 | D35: =SUM(D31:D34) -> 0 | E35: =IF(D35=0,"",D35-C35) | F35: =IF(OR($C$118=0,C35=""),"",C35/$C$118)
A36: Étkezés, bevásárlás
A37: =IF(Január!A37="","",Január!A37) -> Nagybevásárlások | E37: =IF(D37=0,"",D37-B37) | F37: =IF(OR($C$118=0,B37=""),"",B37/$C$118)
A38: =IF(Január!A38="","",Január!A38) -> Drogéria | E38: =IF(D38=0,"",D38-B38) | F38: =IF(OR($C$118=0,B38=""),"",B38/$C$118)
A39: =IF(Január!A39="","",Január!A39) -> Ételrendelés | E39: =IF(D39=0,"",D39-B39) | F39: =IF(OR($C$118=0,B39=""),"",B39/$C$118)
A40: =IF(Január!A40="","",Január!A40) -> Egyéb élelmiszer, bevásárlás | E40: =IF(D40=0,"",D40-B40) | F40: =IF(OR($C$118=0,B40=""),"",B40/$C$118)
...

Sheet Március
A1: =" 💰 HAVI KÖLTSÉGVETÉS — "&UPPER("Március")&" "&'📊 Éves Összesítő'!$B$2 -> 💰 HAVI KÖLTSÉGVETÉS — MÁRCIUS 2026
A2: Kategória / Megnevezés | B2: Összeg (Ft) | C2: Összesítő (Ft) | D2: Tervezett (Ft) | E2: Eltérés a tervtől (− = rossz) | F2: Arány
A3: 💚 BEVÉTELEK
A4: Munkából származó bevétel
A5: =IF(Február!A5="","",Február!A5) -> Munkabér 1 (pl. saját) | E5: =IF(D5=0,"",B5-D5) | F5: =IF(OR($C$16=0,B5=""),"",B5/$C$16)
A6: =IF(Február!A6="","",Február!A6) -> Munkabér 2 (pl. partner) | E6: =IF(D6=0,"",B6-D6) | F6: =IF(OR($C$16=0,B6=""),"",B6/$C$16)
A7: =IF(Február!A7="","",Február!A7) -> Vállalkozói bevétel | E7: =IF(D7=0,"",B7-D7) | F7: =IF(OR($C$16=0,B7=""),"",B7/$C$16)
A8: =IF(Február!A8="","",Február!A8) | E8: =IF(D8=0,"",B8-D8) | F8: =IF(OR($C$16=0,B8=""),"",B8/$C$16)
A9: ∑ Munkából származó bevétel | C9: =SUM(B5:B8) -> 0 | D9: =SUM(D5:D8) -> 0 | E9: =IF(D9=0,"",C9-D9) | F9: =IF(OR($C$16=0,C9=""),"",C9/$C$16)
A10: Egyéb bevétel
A11: =IF(Február!A11="","",Február!A11) -> CSED / GYED / GYES | E11: =IF(D11=0,"",B11-D11) | F11: =IF(OR($C$16=0,B11=""),"",B11/$C$16)
A12: =IF(Február!A12="","",Február!A12) -> Családi pótlék | E12: =IF(D12=0,"",B12-D12) | F12: =IF(OR($C$16=0,B12=""),"",B12/$C$16)
A13: =IF(Február!A13="","",Február!A13) -> Egyéb (lakáskiadás, bónusz stb.) | E13: =IF(D13=0,"",B13-D13) | F13: =IF(OR($C$16=0,B13=""),"",B13/$C$16)
A14: =IF(Február!A14="","",Február!A14) | E14: =IF(D14=0,"",B14-D14) | F14: =IF(OR($C$16=0,B14=""),"",B14/$C$16)
A15: ∑ Egyéb bevétel | C15: =SUM(B11:B14) -> 0 | D15: =SUM(D11:D14) -> 0 | E15: =IF(D15=0,"",C15-D15) | F15: =IF(OR($C$16=0,C15=""),"",C15/$C$16)
A16: ÖSSZESEN: 💚 BEVÉTELEK | C16: =C9+C15 -> 0 | D16: =D9+D15 -> 0 | E16: =IF(D16=0,"",C16-D16) | F16: =IF($C$16=0,"",1)
A17: 💎 MEGTAKARÍTÁSOK
A18: =IF(Február!A18="","",Február!A18) -> Vésztartalék | E18: =IF(D18=0,"",B18-D18) | F18: =IF(OR($C$28=0,B18=""),"",B18/$C$28)
A19: =IF(Február!A19="","",Február!A19) -> Lakástakarékpénztár | E19: =IF(D19=0,"",B19-D19) | F19: =IF(OR($C$28=0,B19=""),"",B19/$C$28)
A20: =IF(Február!A20="","",Február!A20) -> Általános cél | E20: =IF(D20=0,"",B20-D20) | F20: =IF(OR($C$28=0,B20=""),"",B20/$C$28)
A21: =IF(Február!A21="","",Február!A21) -> Hosszú távú (min. 10 éves, általános célú) | E21: =IF(D21=0,"",B21-D21) | F21: =IF(OR($C$28=0,B21=""),"",B21/$C$28)
A22: =IF(Február!A22="","",Február!A22) -> Hosszú távú (min. 10 éves, lakás célú) | E22: =IF(D22=0,"",B22-D22) | F22: =IF(OR($C$28=0,B22=""),"",B22/$C$28)
A23: =IF(Február!A23="","",Február!A23) -> Hosszú távú (min. 10 éves, gyermek jövője célú) | E23: =IF(D23=0,"",B23-D23) | F23: =IF(OR($C$28=0,B23=""),"",B23/$C$28)
A24: =IF(Február!A24="","",Február!A24) -> Hosszú távú (min. 15 éves, nyugdíj célú) | E24: =IF(D24=0,"",B24-D24) | F24: =IF(OR($C$28=0,B24=""),"",B24/$C$28)
A25: =IF(Február!A25="","",Február!A25) -> Nyugdíjbiztosítás | E25: =IF(D25=0,"",B25-D25) | F25: =IF(OR($C$28=0,B25=""),"",B25/$C$28)
A26: =IF(Február!A26="","",Február!A26) | E26: =IF(D26=0,"",B26-D26) | F26: =IF(OR($C$28=0,B26=""),"",B26/$C$28)
A27: =IF(Február!A27="","",Február!A27) | E27: =IF(D27=0,"",B27-D27) | F27: =IF(OR($C$28=0,B27=""),"",B27/$C$28)
A28: ÖSSZESEN: 💎 MEGTAKARÍTÁSOK | C28: =SUM(B18:B27) -> 0 | D28: =SUM(D18:D27) -> 0 | E28: =IF(D28=0,"",C28-D28) | F28: =IF($C$16=0,"",C28/$C$16)
A29: ❤️ KIADÁSOK
A30: Lakhatás
A31: =IF(Február!A31="","",Február!A31) -> Albérleti díj / lakáshitel | E31: =IF(D31=0,"",D31-B31) | F31: =IF(OR($C$118=0,B31=""),"",B31/$C$118)
A32: =IF(Február!A32="","",Február!A32) -> Rezsi (közművek, közös költség) | E32: =IF(D32=0,"",D32-B32) | F32: =IF(OR($C$118=0,B32=""),"",B32/$C$118)
A33: =IF(Február!A33="","",Február!A33) -> Telefon, internet, digitális előfizetések | E33: =IF(D33=0,"",D33-B33) | F33: =IF(OR($C$118=0,B33=""),"",B33/$C$118)
A34: =IF(Február!A34="","",Február!A34) | E34: =IF(D34=0,"",D34-B34) | F34: =IF(OR($C$118=0,B34=""),"",B34/$C$118)
A35: ∑ Lakhatás | C35: =SUM(B31:B34) -> 0 | D35: =SUM(D31:D34) -> 0 | E35: =IF(D35=0,"",D35-C35) | F35: =IF(OR($C$118=0,C35=""),"",C35/$C$118)
A36: Étkezés, bevásárlás
A37: =IF(Február!A37="","",Február!A37) -> Nagybevásárlások | E37: =IF(D37=0,"",D37-B37) | F37: =IF(OR($C$118=0,B37=""),"",B37/$C$118)
A38: =IF(Február!A38="","",Február!A38) -> Drogéria | E38: =IF(D38=0,"",D38-B38) | F38: =IF(OR($C$118=0,B38=""),"",B38/$C$118)
A39: =IF(Február!A39="","",Február!A39) -> Ételrendelés | E39: =IF(D39=0,"",D39-B39) | F39: =IF(OR($C$118=0,B39=""),"",B39/$C$118)
A40: =IF(Február!A40="","",Február!A40) -> Egyéb élelmiszer, bevásárlás | E40: =IF(D40=0,"",D40-B40) | F40: =IF(OR($C$118=0,B40=""),"",B40/$C$118)
...

Sheet Április
A1: =" 💰 HAVI KÖLTSÉGVETÉS — "&UPPER("Április")&" "&'📊 Éves Összesítő'!$B$2 -> 💰 HAVI KÖLTSÉGVETÉS — ÁPRILIS 2026
A2: Kategória / Megnevezés | B2: Összeg (Ft) | C2: Összesítő (Ft) | D2: Tervezett (Ft) | E2: Eltérés a tervtől (− = rossz) | F2: Arány
A3: 💚 BEVÉTELEK
A4: Munkából származó bevétel
A5: =IF(Március!A5="","",Március!A5) -> Munkabér 1 (pl. saját) | E5: =IF(D5=0,"",B5-D5) | F5: =IF(OR($C$16=0,B5=""),"",B5/$C$16)
A6: =IF(Március!A6="","",Március!A6) -> Munkabér 2 (pl. partner) | E6: =IF(D6=0,"",B6-D6) | F6: =IF(OR($C$16=0,B6=""),"",B6/$C$16)
A7: =IF(Március!A7="","",Március!A7) -> Vállalkozói bevétel | E7: =IF(D7=0,"",B7-D7) | F7: =IF(OR($C$16=0,B7=""),"",B7/$C$16)
A8: =IF(Március!A8="","",Március!A8) | E8: =IF(D8=0,"",B8-D8) | F8: =IF(OR($C$16=0,B8=""),"",B8/$C$16)
A9: ∑ Munkából származó bevétel | C9: =SUM(B5:B8) -> 0 | D9: =SUM(D5:D8) -> 0 | E9: =IF(D9=0,"",C9-D9) | F9: =IF(OR($C$16=0,C9=""),"",C9/$C$16)
A10: Egyéb bevétel
A11: =IF(Március!A11="","",Március!A11) -> CSED / GYED / GYES | E11: =IF(D11=0,"",B11-D11) | F11: =IF(OR($C$16=0,B11=""),"",B11/$C$16)
A12: =IF(Március!A12="","",Március!A12) -> Családi pótlék | E12: =IF(D12=0,"",B12-D12) | F12: =IF(OR($C$16=0,B12=""),"",B12/$C$16)
A13: =IF(Március!A13="","",Március!A13) -> Egyéb (lakáskiadás, bónusz stb.) | E13: =IF(D13=0,"",B13-D13) | F13: =IF(OR($C$16=0,B13=""),"",B13/$C$16)
A14: =IF(Március!A14="","",Március!A14) | E14: =IF(D14=0,"",B14-D14) | F14: =IF(OR($C$16=0,B14=""),"",B14/$C$16)
A15: ∑ Egyéb bevétel | C15: =SUM(B11:B14) -> 0 | D15: =SUM(D11:D14) -> 0 | E15: =IF(D15=0,"",C15-D15) | F15: =IF(OR($C$16=0,C15=""),"",C15/$C$16)
A16: ÖSSZESEN: 💚 BEVÉTELEK | C16: =C9+C15 -> 0 | D16: =D9+D15 -> 0 | E16: =IF(D16=0,"",C16-D16) | F16: =IF($C$16=0,"",1)
A17: 💎 MEGTAKARÍTÁSOK
A18: =IF(Március!A18="","",Március!A18) -> Vésztartalék | E18: =IF(D18=0,"",B18-D18) | F18: =IF(OR($C$28=0,B18=""),"",B18/$C$28)
A19: =IF(Március!A19="","",Március!A19) -> Lakástakarékpénztár | E19: =IF(D19=0,"",B19-D19) | F19: =IF(OR($C$28=0,B19=""),"",B19/$C$28)
A20: =IF(Március!A20="","",Március!A20) -> Általános cél | E20: =IF(D20=0,"",B20-D20) | F20: =IF(OR($C$28=0,B20=""),"",B20/$C$28)
A21: =IF(Március!A21="","",Március!A21) -> Hosszú távú (min. 10 éves, általános célú) | E21: =IF(D21=0,"",B21-D21) | F21: =IF(OR($C$28=0,B21=""),"",B21/$C$28)
A22: =IF(Március!A22="","",Március!A22) -> Hosszú távú (min. 10 éves, lakás célú) | E22: =IF(D22=0,"",B22-D22) | F22: =IF(OR($C$28=0,B22=""),"",B22/$C$28)
A23: =IF(Március!A23="","",Március!A23) -> Hosszú távú (min. 10 éves, gyermek jövője célú) | E23: =IF(D23=0,"",B23-D23) | F23: =IF(OR($C$28=0,B23=""),"",B23/$C$28)
A24: =IF(Március!A24="","",Március!A24) -> Hosszú távú (min. 15 éves, nyugdíj célú) | E24: =IF(D24=0,"",B24-D24) | F24: =IF(OR($C$28=0,B24=""),"",B24/$C$28)
A25: =IF(Március!A25="","",Március!A25) -> Nyugdíjbiztosítás | E25: =IF(D25=0,"",B25-D25) | F25: =IF(OR($C$28=0,B25=""),"",B25/$C$28)
A26: =IF(Március!A26="","",Március!A26) | E26: =IF(D26=0,"",B26-D26) | F26: =IF(OR($C$28=0,B26=""),"",B26/$C$28)
A27: =IF(Március!A27="","",Március!A27) | E27: =IF(D27=0,"",B27-D27) | F27: =IF(OR($C$28=0,B27=""),"",B27/$C$28)
A28: ÖSSZESEN: 💎 MEGTAKARÍTÁSOK | C28: =SUM(B18:B27) -> 0 | D28: =SUM(D18:D27) -> 0 | E28: =IF(D28=0,"",C28-D28) | F28: =IF($C$16=0,"",C28/$C$16)
A29: ❤️ KIADÁSOK
A30: Lakhatás
A31: =IF(Március!A31="","",Március!A31) -> Albérleti díj / lakáshitel | E31: =IF(D31=0,"",D31-B31) | F31: =IF(OR($C$118=0,B31=""),"",B31/$C$118)
A32: =IF(Március!A32="","",Március!A32) -> Rezsi (közművek, közös költség) | E32: =IF(D32=0,"",D32-B32) | F32: =IF(OR($C$118=0,B32=""),"",B32/$C$118)
A33: =IF(Március!A33="","",Március!A33) -> Telefon, internet, digitális előfizetések | E33: =IF(D33=0,"",D33-B33) | F33: =IF(OR($C$118=0,B33=""),"",B33/$C$118)
A34: =IF(Március!A34="","",Március!A34) | E34: =IF(D34=0,"",D34-B34) | F34: =IF(OR($C$118=0,B34=""),"",B34/$C$118)
A35: ∑ Lakhatás | C35: =SUM(B31:B34) -> 0 | D35: =SUM(D31:D34) -> 0 | E35: =IF(D35=0,"",D35-C35) | F35: =IF(OR($C$118=0,C35=""),"",C35/$C$118)
A36: Étkezés, bevásárlás
A37: =IF(Március!A37="","",Március!A37) -> Nagybevásárlások | E37: =IF(D37=0,"",D37-B37) | F37: =IF(OR($C$118=0,B37=""),"",B37/$C$118)
A38: =IF(Március!A38="","",Március!A38) -> Drogéria | E38: =IF(D38=0,"",D38-B38) | F38: =IF(OR($C$118=0,B38=""),"",B38/$C$118)
A39: =IF(Március!A39="","",Március!A39) -> Ételrendelés | E39: =IF(D39=0,"",D39-B39) | F39: =IF(OR($C$118=0,B39=""),"",B39/$C$118)
A40: =IF(Március!A40="","",Március!A40) -> Egyéb élelmiszer, bevásárlás | E40: =IF(D40=0,"",D40-B40) | F40: =IF(OR($C$118=0,B40=""),"",B40/$C$118)
...

Sheet Május
A1: =" 💰 HAVI KÖLTSÉGVETÉS — "&UPPER("Május")&" "&'📊 Éves Összesítő'!$B$2 -> 💰 HAVI KÖLTSÉGVETÉS — MÁJUS 2026
A2: Kategória / Megnevezés | B2: Összeg (Ft) | C2: Összesítő (Ft) | D2: Tervezett (Ft) | E2: Eltérés a tervtől (− = rossz) | F2: Arány
A3: 💚 BEVÉTELEK
A4: Munkából származó bevétel
A5: =IF(Április!A5="","",Április!A5) -> Munkabér 1 (pl. saját) | E5: =IF(D5=0,"",B5-D5) | F5: =IF(OR($C$16=0,B5=""),"",B5/$C$16)
A6: =IF(Április!A6="","",Április!A6) -> Munkabér 2 (pl. partner) | E6: =IF(D6=0,"",B6-D6) | F6: =IF(OR($C$16=0,B6=""),"",B6/$C$16)
A7: =IF(Április!A7="","",Április!A7) -> Vállalkozói bevétel | E7: =IF(D7=0,"",B7-D7) | F7: =IF(OR($C$16=0,B7=""),"",B7/$C$16)
A8: =IF(Április!A8="","",Április!A8) | E8: =IF(D8=0,"",B8-D8) | F8: =IF(OR($C$16=0,B8=""),"",B8/$C$16)
A9: ∑ Munkából származó bevétel | C9: =SUM(B5:B8) -> 0 | D9: =SUM(D5:D8) -> 0 | E9: =IF(D9=0,"",C9-D9) | F9: =IF(OR($C$16=0,C9=""),"",C9/$C$16)
A10: Egyéb bevétel
A11: =IF(Április!A11="","",Április!A11) -> CSED / GYED / GYES | E11: =IF(D11=0,"",B11-D11) | F11: =IF(OR($C$16=0,B11=""),"",B11/$C$16)
A12: =IF(Április!A12="","",Április!A12) -> Családi pótlék | E12: =IF(D12=0,"",B12-D12) | F12: =IF(OR($C$16=0,B12=""),"",B12/$C$16)
A13: =IF(Április!A13="","",Április!A13) -> Egyéb (lakáskiadás, bónusz stb.) | E13: =IF(D13=0,"",B13-D13) | F13: =IF(OR($C$16=0,B13=""),"",B13/$C$16)
A14: =IF(Április!A14="","",Április!A14) | E14: =IF(D14=0,"",B14-D14) | F14: =IF(OR($C$16=0,B14=""),"",B14/$C$16)
A15: ∑ Egyéb bevétel | C15: =SUM(B11:B14) -> 0 | D15: =SUM(D11:D14) -> 0 | E15: =IF(D15=0,"",C15-D15) | F15: =IF(OR($C$16=0,C15=""),"",C15/$C$16)
A16: ÖSSZESEN: 💚 BEVÉTELEK | C16: =C9+C15 -> 0 | D16: =D9+D15 -> 0 | E16: =IF(D16=0,"",C16-D16) | F16: =IF($C$16=0,"",1)
A17: 💎 MEGTAKARÍTÁSOK
A18: =IF(Április!A18="","",Április!A18) -> Vésztartalék | E18: =IF(D18=0,"",B18-D18) | F18: =IF(OR($C$28=0,B18=""),"",B18/$C$28)
A19: =IF(Április!A19="","",Április!A19) -> Lakástakarékpénztár | E19: =IF(D19=0,"",B19-D19) | F19: =IF(OR($C$28=0,B19=""),"",B19/$C$28)
A20: =IF(Április!A20="","",Április!A20) -> Általános cél | E20: =IF(D20=0,"",B20-D20) | F20: =IF(OR($C$28=0,B20=""),"",B20/$C$28)
A21: =IF(Április!A21="","",Április!A21) -> Hosszú távú (min. 10 éves, általános célú) | E21: =IF(D21=0,"",B21-D21) | F21: =IF(OR($C$28=0,B21=""),"",B21/$C$28)
A22: =IF(Április!A22="","",Április!A22) -> Hosszú távú (min. 10 éves, lakás célú) | E22: =IF(D22=0,"",B22-D22) | F22: =IF(OR($C$28=0,B22=""),"",B22/$C$28)
A23: =IF(Április!A23="","",Április!A23) -> Hosszú távú (min. 10 éves, gyermek jövője célú) | E23: =IF(D23=0,"",B23-D23) | F23: =IF(OR($C$28=0,B23=""),"",B23/$C$28)
A24: =IF(Április!A24="","",Április!A24) -> Hosszú távú (min. 15 éves, nyugdíj célú) | E24: =IF(D24=0,"",B24-D24) | F24: =IF(OR($C$28=0,B24=""),"",B24/$C$28)
A25: =IF(Április!A25="","",Április!A25) -> Nyugdíjbiztosítás | E25: =IF(D25=0,"",B25-D25) | F25: =IF(OR($C$28=0,B25=""),"",B25/$C$28)
A26: =IF(Április!A26="","",Április!A26) | E26: =IF(D26=0,"",B26-D26) | F26: =IF(OR($C$28=0,B26=""),"",B26/$C$28)
A27: =IF(Április!A27="","",Április!A27) | E27: =IF(D27=0,"",B27-D27) | F27: =IF(OR($C$28=0,B27=""),"",B27/$C$28)
A28: ÖSSZESEN: 💎 MEGTAKARÍTÁSOK | C28: =SUM(B18:B27) -> 0 | D28: =SUM(D18:D27) -> 0 | E28: =IF(D28=0,"",C28-D28) | F28: =IF($C$16=0,"",C28/$C$16)
A29: ❤️ KIADÁSOK
A30: Lakhatás
A31: =IF(Április!A31="","",Április!A31) -> Albérleti díj / lakáshitel | E31: =IF(D31=0,"",D31-B31) | F31: =IF(OR($C$118=0,B31=""),"",B31/$C$118)
A32: =IF(Április!A32="","",Április!A32) -> Rezsi (közművek, közös költség) | E32: =IF(D32=0,"",D32-B32) | F32: =IF(OR($C$118=0,B32=""),"",B32/$C$118)
A33: =IF(Április!A33="","",Április!A33) -> Telefon, internet, digitális előfizetések | E33: =IF(D33=0,"",D33-B33) | F33: =IF(OR($C$118=0,B33=""),"",B33/$C$118)
A34: =IF(Április!A34="","",Április!A34) | E34: =IF(D34=0,"",D34-B34) | F34: =IF(OR($C$118=0,B34=""),"",B34/$C$118)
A35: ∑ Lakhatás | C35: =SUM(B31:B34) -> 0 | D35: =SUM(D31:D34) -> 0 | E35: =IF(D35=0,"",D35-C35) | F35: =IF(OR($C$118=0,C35=""),"",C35/$C$118)
A36: Étkezés, bevásárlás
A37: =IF(Április!A37="","",Április!A37) -> Nagybevásárlások | E37: =IF(D37=0,"",D37-B37) | F37: =IF(OR($C$118=0,B37=""),"",B37/$C$118)
A38: =IF(Április!A38="","",Április!A38) -> Drogéria | E38: =IF(D38=0,"",D38-B38) | F38: =IF(OR($C$118=0,B38=""),"",B38/$C$118)
A39: =IF(Április!A39="","",Április!A39) -> Ételrendelés | E39: =IF(D39=0,"",D39-B39) | F39: =IF(OR($C$118=0,B39=""),"",B39/$C$118)
A40: =IF(Április!A40="","",Április!A40) -> Egyéb élelmiszer, bevásárlás | E40: =IF(D40=0,"",D40-B40) | F40: =IF(OR($C$118=0,B40=""),"",B40/$C$118)
...

Sheet Június
A1: =" 💰 HAVI KÖLTSÉGVETÉS — "&UPPER("Június")&" "&'📊 Éves Összesítő'!$B$2 -> 💰 HAVI KÖLTSÉGVETÉS — JÚNIUS 2026
A2: Kategória / Megnevezés | B2: Összeg (Ft) | C2: Összesítő (Ft) | D2: Tervezett (Ft) | E2: Eltérés a tervtől (− = rossz) | F2: Arány
A3: 💚 BEVÉTELEK
A4: Munkából származó bevétel
A5: =IF(Május!A5="","",Május!A5) -> Munkabér 1 (pl. saját) | E5: =IF(D5=0,"",B5-D5) | F5: =IF(OR($C$16=0,B5=""),"",B5/$C$16)
A6: =IF(Május!A6="","",Május!A6) -> Munkabér 2 (pl. partner) | E6: =IF(D6=0,"",B6-D6) | F6: =IF(OR($C$16=0,B6=""),"",B6/$C$16)
A7: =IF(Május!A7="","",Május!A7) -> Vállalkozói bevétel | E7: =IF(D7=0,"",B7-D7) | F7: =IF(OR($C$16=0,B7=""),"",B7/$C$16)
A8: =IF(Május!A8="","",Május!A8) | E8: =IF(D8=0,"",B8-D8) | F8: =IF(OR($C$16=0,B8=""),"",B8/$C$16)
A9: ∑ Munkából származó bevétel | C9: =SUM(B5:B8) -> 0 | D9: =SUM(D5:D8) -> 0 | E9: =IF(D9=0,"",C9-D9) | F9: =IF(OR($C$16=0,C9=""),"",C9/$C$16)
A10: Egyéb bevétel
A11: =IF(Május!A11="","",Május!A11) -> CSED / GYED / GYES | E11: =IF(D11=0,"",B11-D11) | F11: =IF(OR($C$16=0,B11=""),"",B11/$C$16)
A12: =IF(Május!A12="","",Május!A12) -> Családi pótlék | E12: =IF(D12=0,"",B12-D12) | F12: =IF(OR($C$16=0,B12=""),"",B12/$C$16)
A13: =IF(Május!A13="","",Május!A13) -> Egyéb (lakáskiadás, bónusz stb.) | E13: =IF(D13=0,"",B13-D13) | F13: =IF(OR($C$16=0,B13=""),"",B13/$C$16)
A14: =IF(Május!A14="","",Május!A14) | E14: =IF(D14=0,"",B14-D14) | F14: =IF(OR($C$16=0,B14=""),"",B14/$C$16)
A15: ∑ Egyéb bevétel | C15: =SUM(B11:B14) -> 0 | D15: =SUM(D11:D14) -> 0 | E15: =IF(D15=0,"",C15-D15) | F15: =IF(OR($C$16=0,C15=""),"",C15/$C$16)
A16: ÖSSZESEN: 💚 BEVÉTELEK | C16: =C9+C15 -> 0 | D16: =D9+D15 -> 0 | E16: =IF(D16=0,"",C16-D16) | F16: =IF($C$16=0,"",1)
A17: 💎 MEGTAKARÍTÁSOK
A18: =IF(Május!A18="","",Május!A18) -> Vésztartalék | E18: =IF(D18=0,"",B18-D18) | F18: =IF(OR($C$28=0,B18=""),"",B18/$C$28)
A19: =IF(Május!A19="","",Május!A19) -> Lakástakarékpénztár | E19: =IF(D19=0,"",B19-D19) | F19: =IF(OR($C$28=0,B19=""),"",B19/$C$28)
A20: =IF(Május!A20="","",Május!A20) -> Általános cél | E20: =IF(D20=0,"",B20-D20) | F20: =IF(OR($C$28=0,B20=""),"",B20/$C$28)
A21: =IF(Május!A21="","",Május!A21) -> Hosszú távú (min. 10 éves, általános célú) | E21: =IF(D21=0,"",B21-D21) | F21: =IF(OR($C$28=0,B21=""),"",B21/$C$28)
A22: =IF(Május!A22="","",Május!A22) -> Hosszú távú (min. 10 éves, lakás célú) | E22: =IF(D22=0,"",B22-D22) | F22: =IF(OR($C$28=0,B22=""),"",B22/$C$28)
A23: =IF(Május!A23="","",Május!A23) -> Hosszú távú (min. 10 éves, gyermek jövője célú) | E23: =IF(D23=0,"",B23-D23) | F23: =IF(OR($C$28=0,B23=""),"",B23/$C$28)
A24: =IF(Május!A24="","",Május!A24) -> Hosszú távú (min. 15 éves, nyugdíj célú) | E24: =IF(D24=0,"",B24-D24) | F24: =IF(OR($C$28=0,B24=""),"",B24/$C$28)
A25: =IF(Május!A25="","",Május!A25) -> Nyugdíjbiztosítás | E25: =IF(D25=0,"",B25-D25) | F25: =IF(OR($C$28=0,B25=""),"",B25/$C$28)
A26: =IF(Május!A26="","",Május!A26) | E26: =IF(D26=0,"",B26-D26) | F26: =IF(OR($C$28=0,B26=""),"",B26/$C$28)
A27: =IF(Május!A27="","",Május!A27) | E27: =IF(D27=0,"",B27-D27) | F27: =IF(OR($C$28=0,B27=""),"",B27/$C$28)
A28: ÖSSZESEN: 💎 MEGTAKARÍTÁSOK | C28: =SUM(B18:B27) -> 0 | D28: =SUM(D18:D27) -> 0 | E28: =IF(D28=0,"",C28-D28) | F28: =IF($C$16=0,"",C28/$C$16)
A29: ❤️ KIADÁSOK
A30: Lakhatás
